Workbook

Sheet ESTUDIANTE 1
D2: LISTA DE COTEJO DE PROYECTO / ACTITUD-SER
B4: Indique con una “X” la etapa realizada por el estudiante:
G5: =IF(I10="Cuarto","X",IF(I10="Quinto","X",IF(I10="Sexto","X",""))) -> X | P5: =IF(I10="Séptimo","X",IF(I10="Octavo","X",IF(I10="Noveno","X",""))) | X5: =IF(I10="Décimo","X","")
C6: 1a Estancia | K6: 2a Estancia | U6: Estadía | Y6: GRUPO:
Z8: PROYECTO:
B9: PERIODO | I9: CUATRIMESTRE | Y9: CRITERIOS DE DESEMPEÑO
B10: Septiembre-Diciembre 2025 | I10: Sexto | Y10: Competente | AB10: 10
Y11: Independiente | AB11: 9
B12: MATRÍCULA: | Y12: Básico Avanzado | AB12: 8
B13: NOMBRE DEL ALUMNO: | Y13: Básico Umbral | AB13: 7
B14: CARRERA: | C14: INGENIERÍA EN SOFTWARE | Y14: No competente | AB14: 6
B15: TÍTULO DEL PROYECTO:
B16: NOMBRE DE LA EMPRESA:
B17: ASESOR EMPRESARIAL:
B18: INSTRUCCIONES: Escriba la calificación que corresponda a cada criterio. (Saber y Saber Hacer)
B19: PARCIAL | C19: CRITERIO | U19: FECHA (dd-mm-aa) | Y19: NIVEL DE COMPETENCIA OBTENIDA DE MANERA SUMATIVA EN LAS ENTREGAS PARCIALES DEL PROYECTO | AA19: Observaciones
B23: TERCERO | C23: Empastado de acuerdo a indicaciones (Sólo aplica en Estadía) | AA23: NINGUNA
C24: Hoja en blanco
C25: Carátula | U25: 16 - 28 NOV
C26: AGRADECIMIENTOS
C27: ÍNDICE GENERAL
C28: ÍNDICE DE TABLAS
C29: ÍNDICE DE FIGURAS
C30: RESUMEN
C31: ABSTRACT
C32: INTRODUCCIÓN
B33: PRIMERO | C33: ANTECEDENTES | U33: 1 - 5 SEPT. | AA33: CALIFICACIÓN 1er PARCIAL
C34: PLANTEAMIENTO DEL PROBLEMA | U34: 7 - 12 SEPT.
C35: JUSTIFICACIÓN | U35: 14 - 19 SEPT
C36: OBJETIVO GENERAL | U36: 21 - 26 SEPT.
C37: OBJETIVOS ESPECÍFICOS | U37: 21 - 26 SEPT. | AA37: =SUM(Y33:Z37)/5 -> 0
B38: SEGUNDO | C38: MARCO TEÓRICO | U38: 28 SEPT - 03 OCT | AA38: CALIFICACIÓN 2doPARCIAL
C39: METODOLOGÍA | U39: 05 - 10 OCT
C40: CRONOGRAMA | U40: 12 - 17 OCT
C41: DESARROLLO DEL PROYECTO | U41: 19 - 31 OCT | AA41: =SUM(Y38:Z41)/4 -> 0
B42: TERCERO | C42: RESULTADOS | U42: 02 - 07 NOV | AA42: CALIFICACIÓN 3erPARCIAL
C43: CONCLUSIONES Y RECOMENDACIONES | U43: 09 - 13 NOV
C44: REFERENCIAS BIBLIOGRÁFICAS | U44: 09 - 14 NOV
C45: ANEXOS | U45: 16 - 28 NOV | AA45: =(SUM(Y25:Z32)+SUM(Y42:Z45))/12 -> 0
B46: ACTITUD DEL ESTUDIANTE (SER) | U46: Número de Parcial
...

Sheet ESTUDIANTE 2
D2: LISTA DE COTEJO DE PROYECTO / ACTITUD-SER
B4: Indique con una “X” la etapa realizada por el estudiante:
G5: =IF(I10="Cuarto","X",IF(I10="Quinto","X",IF(I10="Sexto","X",""))) -> X | P5: =IF(I10="Séptimo","X",IF(I10="Octavo","X",IF(I10="Noveno","X",""))) | X5: =IF(I10="Décimo","X","")
C6: 1a Estancia | K6: 2a Estancia | U6: Estadía | Y6: GRUPO: | AA6: =_xlfn.CONCAT('ESTUDIANTE 1'!AA6:AB6)
Z8: PROYECTO: | AA8: =_xlfn.CONCAT('ESTUDIANTE 1'!AA8:AB8)
B9: PERIODO | I9: CUATRIMESTRE | Y9: CRITERIOS DE DESEMPEÑO
B10: =_xlfn.CONCAT('ESTUDIANTE 1'!B10:E10) -> Septiembre-Diciembre 2025 | I10: =_xlfn.CONCAT('ESTUDIANTE 1'!I10:P10) -> Sexto | Y10: Competente | AB10: 10
Y11: Independiente | AB11: 9
B12: MATRÍCULA: | Y12: Básico Avanzado | AB12: 8
B13: NOMBRE DEL ALUMNO: | Y13: Básico Umbral | AB13: 7
B14: CARRERA: | C14: =_xlfn.CONCAT('ESTUDIANTE 1'!C14:U14) -> INGENIERÍA EN SOFTWARE | Y14: No competente | AB14: 6
B15: TÍTULO DEL PROYECTO: | D15: =_xlfn.CONCAT('ESTUDIANTE 1'!D15:AC15)
B16: NOMBRE DE LA EMPRESA: | D16: =_xlfn.CONCAT('ESTUDIANTE 1'!D16:AC16)
B17: ASESOR EMPRESARIAL: | D17: =_xlfn.CONCAT('ESTUDIANTE 1'!D17:X17)
B18: INSTRUCCIONES: Escriba la calificación que corresponda a cada criterio. (Saber y Saber Hacer)
B19: PARCIAL | C19: CRITERIO | U19: FECHA (dd-mm-aa) | Y19: NIVEL DE COMPETENCIA OBTENIDA DE MANERA SUMATIVA EN LAS ENTREGAS PARCIALES DEL PROYECTO | AA19: Observaciones
B23: TERCERO | C23: Empastado de acuerdo a indicaciones (Sólo aplica en Estadía) | AA23: NINGUNA
C24: Hoja en blanco
C25: Carátula | U25: 16 - 28 NOV
C26: AGRADECIMIENTOS
C27: ÍNDICE GENERAL
C28: ÍNDICE DE TABLAS
C29: ÍNDICE DE FIGURAS
C30: RESUMEN
C31: ABSTRACT
C32: INTRODUCCIÓN
B33: PRIMERO | C33: ANTECEDENTES | U33: 1 - 5 SEPT. | AA33: CALIFICACIÓN 1er PARCIAL
C34: PLANTEAMIENTO DEL PROBLEMA | U34: 7 - 12 SEPT.
C35: JUSTIFICACIÓN | U35: 14 - 19 SEPT
C36: OBJETIVO GENERAL | U36: 21 - 26 SEPT.
C37: OBJETIVOS ESPECÍFICOS | U37: 21 - 26 SEPT. | AA37: =SUM(Y33:Z37)/5 -> 0
B38: SEGUNDO | C38: MARCO TEÓRICO | U38: 28 SEPT - 03 OCT | AA38: CALIFICACIÓN 2doPARCIAL
C39: METODOLOGÍA | U39: 05 - 10 OCT
C40: CRONOGRAMA | U40: 12 - 17 OCT
C41: DESARROLLO DEL PROYECTO | U41: 19 - 31 OCT | AA41: =SUM(Y38:Z41)/4 -> 0
B42: TERCERO | C42: RESULTADOS | U42: 02 - 07 NOV | AA42: CALIFICACIÓN 3erPARCIAL
C43: CONCLUSIONES Y RECOMENDACIONES | U43: 09 - 13 NOV
C44: REFERENCIAS BIBLIOGRÁFICAS | U44: 09 - 14 NOV
C45: ANEXOS | U45: 16 - 28 NOV | AA45: =(SUM(Y25:Z32)+SUM(Y42:Z45))/12 -> 0
B46: ACTITUD DEL ESTUDIANTE (SER) | U46: Número de Parcial
...

Sheet ESTUDIANTE 3
D2: LISTA DE COTEJO DE PROYECTO / ACTITUD-SER
B4: Indique con una “X” la etapa realizada por el estudiante:
G5: =IF(I10="Cuarto","X",IF(I10="Quinto","X",IF(I10="Sexto","X",""))) -> X | P5: =IF(I10="Séptimo","X",IF(I10="Octavo","X",IF(I10="Noveno","X",""))) | X5: =IF(I10="Décimo","X","")
C6: 1a Estancia | K6: 2a Estancia | U6: Estadía | Y6: GRUPO: | AA6: =_xlfn.CONCAT('ESTUDIANTE 1'!AA6:AB6)
Z8: PROYECTO: | AA8: =_xlfn.CONCAT('ESTUDIANTE 1'!AA8:AB8)
B9: PERIODO | I9: CUATRIMESTRE | Y9: CRITERIOS DE DESEMPEÑO
B10: =_xlfn.CONCAT('ESTUDIANTE 1'!B10:E10) -> Septiembre-Diciembre 2025 | I10: =_xlfn.CONCAT('ESTUDIANTE 1'!I10:P10) -> Sexto | Y10: Competente | AB10: 10
Y11: Independiente | AB11: 9
B12: MATRÍCULA: | Y12: Básico Avanzado | AB12: 8
B13: NOMBRE DEL ALUMNO: | Y13: Básico Umbral | AB13: 7
B14: CARRERA: | C14: =_xlfn.CONCAT('ESTUDIANTE 1'!C14:U14) -> INGENIERÍA EN SOFTWARE | Y14: No competente | AB14: 6
B15: TÍTULO DEL PROYECTO: | D15: =_xlfn.CONCAT('ESTUDIANTE 1'!D15:AC15)
B16: NOMBRE DE LA EMPRESA: | D16: =_xlfn.CONCAT('ESTUDIANTE 1'!D16:AC16)
B17: ASESOR EMPRESARIAL: | D17: =_xlfn.CONCAT('ESTUDIANTE 1'!D17:X17)
B18: INSTRUCCIONES: Escriba la calificación que corresponda a cada criterio. (Saber y Saber Hacer)
B19: PARCIAL | C19: CRITERIO | U19: FECHA (dd-mm-aa) | Y19: NIVEL DE COMPETENCIA OBTENIDA DE MANERA SUMATIVA EN LAS ENTREGAS PARCIALES DEL PROYECTO | AA19: Observaciones
B23: TERCERO | C23: Empastado de acuerdo a indicaciones (Sólo aplica en Estadía) | AA23: NINGUNA
C24: Hoja en blanco
C25: Carátula | U25: 16 - 28 NOV
C26: AGRADECIMIENTOS
C27: ÍNDICE GENERAL
C28: ÍNDICE DE TABLAS
C29: ÍNDICE DE FIGURAS
C30: RESUMEN
C31: ABSTRACT
C32: INTRODUCCIÓN
B33: PRIMERO | C33: ANTECEDENTES | U33: 1 - 5 SEPT. | AA33: CALIFICACIÓN 1er PARCIAL
C34: PLANTEAMIENTO DEL PROBLEMA | U34: 7 - 12 SEPT.
C35: JUSTIFICACIÓN | U35: 14 - 19 SEPT
C36: OBJETIVO GENERAL | U36: 21 - 26 SEPT.
C37: OBJETIVOS ESPECÍFICOS | U37: 21 - 26 SEPT. | AA37: =SUM(Y33:Z37)/5 -> 0
B38: SEGUNDO | C38: MARCO TEÓRICO | U38: 28 SEPT - 03 OCT | AA38: CALIFICACIÓN 2doPARCIAL
C39: METODOLOGÍA | U39: 05 - 10 OCT
C40: CRONOGRAMA | U40: 12 - 17 OCT
C41: DESARROLLO DEL PROYECTO | U41: 19 - 31 OCT | AA41: =SUM(Y38:Z41)/4 -> 0
B42: TERCERO | C42: RESULTADOS | U42: 02 - 07 NOV | AA42: CALIFICACIÓN 3erPARCIAL
C43: CONCLUSIONES Y RECOMENDACIONES | U43: 09 - 13 NOV
C44: REFERENCIAS BIBLIOGRÁFICAS | U44: 09 - 14 NOV
C45: ANEXOS | U45: 16 - 28 NOV | AA45: =(SUM(Y25:Z32)+SUM(Y42:Z45))/12 -> 0
B46: ACTITUD DEL ESTUDIANTE (SER) | U46: Número de Parcial
...

Sheet ESTUDIANTE 4
D2: LISTA DE COTEJO DE PROYECTO / ACTITUD-SER
B4: Indique con una “X” la etapa realizada por el estudiante:
P5: =IF(I10="Séptimo","X",IF(I10="Octavo","X",IF(I10="Noveno","X",""))) | X5: X
C6: 1a Estancia | K6: 2a Estancia | U6: Estadía | Y6: GRUPO: | AA6: 21026
Z8: PROYECTO: | AA8: =_xlfn.CONCAT('ESTUDIANTE 1'!AA8:AB8)
B9: PERIODO | I9: CUATRIMESTRE | Y9: CRITERIOS DE DESEMPEÑO
B10: =_xlfn.CONCAT('ESTUDIANTE 1'!B10:E10) -> Septiembre-Diciembre 2025 | I10: Decimo | Y10: Competente | AB10: 10
Y11: Independiente | AB11: 9
B12: MATRÍCULA: | C12: 1323144296 | Y12: Básico Avanzado | AB12: 8
B13: NOMBRE DEL ALUMNO: | Y13: Básico Umbral | AB13: 7
B14: CARRERA: | C14: =_xlfn.CONCAT('ESTUDIANTE 2'!C14:U14) -> INGENIERÍA EN SOFTWARE | Y14: No competente | AB14: 6
B15: TÍTULO DEL PROYECTO: | D15: =_xlfn.CONCAT('ESTUDIANTE 1'!D15:AC15)
B16: NOMBRE DE LA EMPRESA: | D16: =_xlfn.CONCAT('ESTUDIANTE 1'!D16:AC16)
B17: ASESOR EMPRESARIAL: | D17: =_xlfn.CONCAT('ESTUDIANTE 1'!D17:X17)
B18: INSTRUCCIONES: Escriba la calificación que corresponda a cada criterio. (Saber y Saber Hacer)
B19: PARCIAL | C19: CRITERIO | U19: FECHA (dd-mm-aa) | Y19: NIVEL DE COMPETENCIA OBTENIDA DE MANERA SUMATIVA EN LAS ENTREGAS PARCIALES DEL PROYECTO | AA19: Observaciones
B23: TERCERO | C23: Empastado de acuerdo a indicaciones (Sólo aplica en Estadía) | AA23: NINGUNA
C24: Hoja en blanco
C25: Carátula | U25: 16 - 28 NOV
C26: AGRADECIMIENTOS
C27: ÍNDICE GENERAL
C28: ÍNDICE DE TABLAS
C29: ÍNDICE DE FIGURAS
C30: RESUMEN
C31: ABSTRACT
C32: INTRODUCCIÓN
B33: PRIMERO | C33: ANTECEDENTES | U33: 1 - 5 SEPT. | AA33: CALIFICACIÓN 1er PARCIAL
C34: PLANTEAMIENTO DEL PROBLEMA | U34: 7 - 12 SEPT.
C35: JUSTIFICACIÓN | U35: 14 - 19 SEPT
C36: OBJETIVO GENERAL | U36: 21 - 26 SEPT.
C37: OBJETIVOS ESPECÍFICOS | U37: 21 - 26 SEPT. | AA37: =SUM(Y33:Z37)/5 -> 0
B38: SEGUNDO | C38: MARCO TEÓRICO | U38: 28 SEPT - 03 OCT | AA38: CALIFICACIÓN 2doPARCIAL
C39: METODOLOGÍA | U39: 05 - 10 OCT
C40: CRONOGRAMA | U40: 12 - 17 OCT
C41: DESARROLLO DEL PROYECTO | U41: 19 - 31 OCT | AA41: =SUM(Y38:Z41)/4 -> 0
B42: TERCERO | C42: RESULTADOS | U42: 02 - 07 NOV | AA42: CALIFICACIÓN 3erPARCIAL
C43: CONCLUSIONES Y RECOMENDACIONES | U43: 09 - 13 NOV
C44: REFERENCIAS BIBLIOGRÁFICAS | U44: 09 - 14 NOV
C45: ANEXOS | U45: 16 - 28 NOV | AA45: =(SUM(Y25:Z32)+SUM(Y42:Z45))/12 -> 0
B46: ACTITUD DEL ESTUDIANTE (SER) | U46: Número de Parcial
...

Sheet ESTUDIANTE 5
D2: LISTA DE COTEJO DE PROYECTO / ACTITUD-SER
B4: Indique con una “X” la etapa realizada por el estudiante:
G5: =IF(I10="Cuarto","X",IF(I10="Quinto","X",IF(I10="Sexto","X",""))) -> X | P5: =IF(I10="Séptimo","X",IF(I10="Octavo","X",IF(I10="Noveno","X",""))) | X5: =IF(I10="Décimo","X","")
C6: 1a Estancia | K6: 2a Estancia | U6: Estadía | Y6: GRUPO: | AA6: =_xlfn.CONCAT('ESTUDIANTE 1'!AA6:AB6)
Z8: PROYECTO: | AA8: =_xlfn.CONCAT('ESTUDIANTE 1'!AA8:AB8)
B9: PERIODO | I9: CUATRIMESTRE | Y9: CRITERIOS DE DESEMPEÑO
B10: =_xlfn.CONCAT('ESTUDIANTE 1'!B10:E10) -> Septiembre-Diciembre 2025 | I10: =_xlfn.CONCAT('ESTUDIANTE 1'!I10:P10) -> Sexto | Y10: Competente | AB10: 10
Y11: Independiente | AB11: 9
B12: MATRÍCULA: | Y12: Básico Avanzado | AB12: 8
B13: NOMBRE DEL ALUMNO: | Y13: Básico Umbral | AB13: 7
B14: CARRERA: | C14: =_xlfn.CONCAT('ESTUDIANTE 1'!C14:U14) -> INGENIERÍA EN SOFTWARE | Y14: No competente | AB14: 6
B15: TÍTULO DEL PROYECTO: | D15: =_xlfn.CONCAT('ESTUDIANTE 1'!D15:AC15)
B16: NOMBRE DE LA EMPRESA: | D16: =_xlfn.CONCAT('ESTUDIANTE 1'!D16:AC16)
B17: ASESOR EMPRESARIAL: | D17: =_xlfn.CONCAT('ESTUDIANTE 1'!D17:X17)
B18: INSTRUCCIONES: Escriba la calificación que corresponda a cada criterio. (Saber y Saber Hacer)
B19: PARCIAL | C19: CRITERIO | U19: FECHA (dd-mm-aa) | Y19: NIVEL DE COMPETENCIA OBTENIDA DE MANERA SUMATIVA EN LAS ENTREGAS PARCIALES DEL PROYECTO | AA19: Observaciones
B23: TERCERO | C23: Empastado de acuerdo a indicaciones (Sólo aplica en Estadía) | AA23: NINGUNA
C24: Hoja en blanco
C25: Carátula | U25: 16 - 28 NOV
C26: AGRADECIMIENTOS
C27: ÍNDICE GENERAL
C28: ÍNDICE DE TABLAS
C29: ÍNDICE DE FIGURAS
C30: RESUMEN
C31: ABSTRACT
C32: INTRODUCCIÓN
B33: PRIMERO | C33: ANTECEDENTES | U33: 1 - 5 SEPT. | AA33: CALIFICACIÓN 1er PARCIAL
C34: PLANTEAMIENTO DEL PROBLEMA | U34: 7 - 12 SEPT.
C35: JUSTIFICACIÓN | U35: 14 - 19 SEPT
C36: OBJETIVO GENERAL | U36: 21 - 26 SEPT.
C37: OBJETIVOS ESPECÍFICOS | U37: 21 - 26 SEPT. | AA37: =SUM(Y33:Z37)/5 -> 0
B38: SEGUNDO | C38: MARCO TEÓRICO | U38: 28 SEPT - 03 OCT | AA38: CALIFICACIÓN 2doPARCIAL
C39: METODOLOGÍA | U39: 05 - 10 OCT
C40: CRONOGRAMA | U40: 12 - 17 OCT
C41: DESARROLLO DEL PROYECTO | U41: 19 - 31 OCT | AA41: =SUM(Y38:Z41)/4 -> 0
B42: TERCERO | C42: RESULTADOS | U42: 02 - 07 NOV | AA42: CALIFICACIÓN 3erPARCIAL
C43: CONCLUSIONES Y RECOMENDACIONES | U43: 09 - 13 NOV
C44: REFERENCIAS BIBLIOGRÁFICAS | U44: 09 - 14 NOV
C45: ANEXOS | U45: 16 - 28 NOV | AA45: =(SUM(Y25:Z32)+SUM(Y42:Z45))/12 -> 0
B46: ACTITUD DEL ESTUDIANTE (SER) | U46: Número de Parcial
...
